<?xml version="1.0"?>
<robot xmlns:xacro="http://ros.org/wiki/xacro">

<xacro:property name="mmTom" value="0.001" />
<xacro:property name="mm2Tom2" value="${0.001*0.001}" />
<xacro:property name="tonsToKg" value="1000.0" />

<xacro:property name="PI" value="3.14159265359" />
<xacro:property name="PI_2" value="1.57079632679" />


<!-- LINKS -->

<!-- ********************RIGHT LEG******************** -->

<link name ="RHipMot">
    <inertial>
      <origin xyz="${-1.0348188e+02*mmTom} ${-1.0919813e+02*mmTom} ${-6.4924056e+01*mmTom}" rpy="0 0 0"/>
      <mass value="${3.7958197e-03*tonsToKg}"/>
      <inertia ixx="${1.5639017e+01*mm2Tom2*tonsToKg}"  ixy="${1.8504661*mm2Tom2*tonsToKg}"  ixz="${2.3907793*mm2Tom2*tonsToKg}" iyy="${2.3519749e+01*mm2Tom2*tonsToKg}" iyz="${-2.3303162*mm2Tom2*tonsToKg}" izz="${2.0953643e+01*mm2Tom2*tonsToKg}" />
    </inertial>
    <visual>
      <origin xyz="0 0 0" rpy="0 0 0"/>
      <geometry name="RHipMot_visual">
        <mesh filename="meshes/HipRoll.STL" scale="0.001 0.001 0.001" />
      </geometry>
      <material name="dark_grey"/>
    </visual>
    <collision>
      <origin xyz="0 0 0" rpy="0 0 0"/>
      <geometry name="RHipMot_collision">
        <mesh filename="meshes/simple/HipRoll.STL" scale="0.001 0.001 0.001" />
      </geometry>             
    </collision>
</link>

  <link name ="RThighUpLeg">
    <inertial>
      <origin xyz="${-5.2929709*mmTom} ${-2.2561833e+01*mmTom} ${5.6701669*mmTom}" rpy="0 0 0"/>
      <mass value="3.2402068"/>
      <inertia ixx="${1.0102097e+04*mm2Tom2}"  ixy="${1.0858487e+02*mm2Tom2}"  ixz="${2.5291395e+02*mm2Tom2}" iyy="${6.7147000e+03*mm2Tom2}" iyz="${8.3447072e+01*mm2Tom2}" izz="${1.0485130e+04*mm2Tom2}" />
    </inertial>
    <visual>
      <origin xyz="0 0 0" rpy="0 0 0"/>
      <geometry name="RThighUpLeg_visual">
        <mesh filename="meshes/HipYaw.STL" scale="0.001 0.001 0.001" />
      </geometry>
      <material name="dark_grey"/>
    </visual>
    <collision>
      <origin xyz="0 0 0" rpy="0 0 0"/>
      <geometry name="RThighUpLeg_collision">
        <mesh filename="meshes/simple/HipYaw.STL" scale="0.001 0.001 0.001" />
      </geometry>             
    </collision>
  </link>

  <link name ="RThighLowLeg">
    <inertial>
      <origin xyz="${3.7746286e+01*mmTom} ${-2.8539939e+01*mmTom} ${-1.9310133e+02*mmTom}" rpy="0 0 0"/>
      <mass value="5.0950736"/>
      <inertia ixx="${5.1607858e+04*mm2Tom2}"  ixy="${2.2253472e+03*mm2Tom2}"  ixz="${2.4529790e+03*mm2Tom2}" iyy="${4.4349153e+04*mm2Tom2}" iyz="${-4.1006942e+03*mm2Tom2}" izz="${2.3374453e+04*mm2Tom2}" />
    </inertial>
    <visual>
      <origin xyz="0 0 0" rpy="0 0 0"/>
      <geometry name="RThighLowLeg_visual">
        <mesh filename="meshes/HipPitch.STL" scale="0.001 0.001 0.001" />
      </geometry>
      <material name="grey"/>
    </visual>
    <collision>
      <origin xyz="0 0 0" rpy="0 0 0"/>
      <geometry name="RThighLowLeg_collision">
        <mesh filename="meshes/simple/HipPitch.STL" scale="0.001 0.001 0.001" />
      </geometry>             
    </collision>
  </link>

  <link name ="RLowLeg">
    <inertial>
      <origin xyz="${-5.0828668*mmTom} ${3.7732093*mmTom} ${-7.2605017e+01*mmTom}" rpy="0 0 0"/>
      <mass value="5.6495309"/>
      <inertia ixx="${1.0535542e+05*mm2Tom2}"  ixy="${-5.8199221e+02*mm2Tom2}"  ixz="${1.6743598e+03*mm2Tom2}" iyy="${9.7857796e+04*mm2Tom2}" iyz="${-3.3770181e+03*mm2Tom2}" izz="${2.0854086e+04*mm2Tom2}" />
    </inertial>
    <visual>
      <origin xyz="0 0 0" rpy="0 0 0"/>
      <geometry name="RLowLeg_visual">
        <mesh filename="meshes/KneePitchCalf.STL" scale="0.001 0.001 0.001" />
      </geometry>
      <material name="dark_grey"/>
    </visual>
    <collision>
      <origin xyz="0 0 0" rpy="0 0 0"/>
      <geometry name="RLowLeg_collision">
        <mesh filename="meshes/simple/KneePitchCalf.STL" scale="0.001 0.001 0.001" />
      </geometry>             
    </collision>
  </link>

  <link name ="RFootmot">
    <inertial>
      <origin xyz="${-2.2024173e+01*mmTom} ${2.5677238*mmTom} ${9.4588455e-01*mmTom}" rpy="0 0 0"/>
      <mass value="3.2844159"/>
      <inertia ixx="${7.5550679e+03*mm2Tom2}"  ixy="${6.7488292e+02*mm2Tom2}"  ixz="${5.8332889e+01*mm2Tom2}" iyy="${1.1241163e+04*mm2Tom2}" iyz="${-1.4552081e+02*mm2Tom2}" izz="${1.3391865e+04*mm2Tom2}" />
    </inertial>
    <visual>
      <origin xyz="0 0 0" rpy="0 0 0"/>
      <geometry name="RFootmot_visual">
        <mesh filename="meshes/AnklePitch.STL" scale="0.001 0.001 0.001" />
      </geometry>
      <material name="dark_grey"/>
    </visual>
    <collision>
      <origin xyz="0 0 0" rpy="0 0 0"/>
      <geometry name="RFootmot_collision">
        <mesh filename="meshes/simple/AnklePitch.STL" scale="0.001 0.001 0.001" />
      </geometry>             
    </collision>
  </link>

  <link name ="RFoot">
     <inertial>
        <xacro:if value="${BIGMAN_NEW_FEET}">
          <origin xyz="-0.00653584 -0.00479384 -0.10180375" rpy="0 0 0"/>
          <mass value="3.42638110"/>
          <inertia ixx="0.01032886"  ixy="-0.00016407"  ixz="-0.00201294" iyy="0.02854025" iyz="0.00046315" izz="0.02799499" />
        </xacro:if>
        <xacro:unless value="${BIGMAN_NEW_FEET}">
          <origin xyz="0.01282904 -0.00463694 -0.10109499" rpy="0 0 0"/>
          <mass value="3.33109981"/>
          <inertia ixx="0.01006627"  ixy="-0.00051955"  ixz="-0.00374069" iyy="0.02882577" iyz="0.00044505" izz="0.02819025" />
        </xacro:unless>
      </inertial>
    <visual>
      <origin xyz="0 0 0" rpy="0 0 0"/>
      <geometry name="RFoot_visual">
        <xacro:if value="${BIGMAN_NEW_FEET}">
              <mesh filename="meshes/NewFoot.STL" scale="0.001 0.001 0.001"/>
        </xacro:if>
        <xacro:unless value="${BIGMAN_NEW_FEET}">
              <mesh filename="meshes/Foot.STL" scale="0.001 -0.001 0.001"/>
        </xacro:unless>
      </geometry>
      <material name="dark_grey"/>
    </visual> 
    <collision>
      <!--<origin xyz="0 0 0" rpy="0 0 0"/>
      <geometry name="RFoot_collision">
        <mesh filename="meshes/simple/Foot.STL" scale="0.001 -0.001 0.001"/>
      </geometry>-->
     <xacro:if value="${BIGMAN_NEW_FEET}">
       <origin xyz="0.005 -0.01 -0.1359" rpy="0 0 0"/>
       <geometry>
         <box size="0.32 0.16 0.015" />
       </geometry>
     </xacro:if>
     <xacro:unless value="${BIGMAN_NEW_FEET}">
       <origin xyz="0.047 -0.01 -0.1359" rpy="0 0 0"/>
       <geometry>
         <box size="0.306 0.16 0.015" />
       </geometry>
     </xacro:unless>             
    </collision>             
  </link>


<!-- ********************LEFT LEG******************** -->
  <link name ="LHipMot">
    <inertial>
      <origin xyz="${-1.0348188e+02*mmTom} ${1.0919813e+02*mmTom} ${-6.4924056e+01*mmTom}" rpy="0 0 0"/>
      <mass value="${3.7958197e-03*tonsToKg}"/>
      <inertia ixx="${1.5639017e+01*mm2Tom2*tonsToKg}"  ixy="${-1.8504661*mm2Tom2*tonsToKg}"  ixz="${2.3907793*mm2Tom2*tonsToKg}" iyy="${2.3519749e+01*mm2Tom2*tonsToKg}" iyz="${2.3303162*mm2Tom2*tonsToKg}" izz="${2.0953643e+01*mm2Tom2*tonsToKg}" />
    </inertial>
    <visual>
      <origin xyz="0 0 0" rpy="0 0 0"/>
      <geometry name="LHipMot_visual">
        <mesh filename="meshes/HipRoll.STL" scale="0.001 -0.001 0.001" />
      </geometry>
      <material name="dark_grey"/>
    </visual>
    <collision>
      <origin xyz="0 0 0" rpy="0 0 0"/>
      <geometry name="LHipMot_collision">
        <mesh filename="meshes/simple/HipRoll.STL" scale="0.001 -0.001 0.001" />
      </geometry>             
    </collision>
  </link>

  <link name ="LThighUpLeg">
    <inertial>
      <origin xyz="${-5.2929709*mmTom} ${2.2561833e+01*mmTom} ${5.6701669*mmTom}" rpy="0 0 0"/>
      <mass value="3.2402068"/>
      <inertia ixx="${1.0102097e+04*mm2Tom2}"  ixy="${-1.0858487e+02*mm2Tom2}"  ixz="${2.5291395e+02*mm2Tom2}" iyy="${6.7147000e+03*mm2Tom2}" iyz="${-8.3447072e+01*mm2Tom2}" izz="${1.0485130e+04*mm2Tom2}" />
    </inertial>
    <visual>
      <origin xyz="0 0 0" rpy="0 0 0"/>
      <geometry name="LThighUpLeg_visual">
        <mesh filename="meshes/HipYaw.STL" scale="0.001 -0.001 0.001" />
      </geometry>
      <material name="dark_grey"/>
    </visual>
    <collision>
      <origin xyz="0 0 0" rpy="0 0 0"/>
      <geometry name="LThighUpLeg_collision">
        <mesh filename="meshes/simple/HipYaw.STL" scale="0.001 -0.001 0.001" />
      </geometry>             
    </collision>
  </link>

  <link name ="LThighLowLeg">
    <inertial>
      <origin xyz="${3.7746286e+01*mmTom} ${2.8539939e+01*mmTom} ${-1.9310133e+02*mmTom}" rpy="0 0 0"/>
      <mass value="5.0950736"/>
      <inertia ixx="${5.1607858e+04*mm2Tom2}"  ixy="${-2.2253472e+03*mm2Tom2}"  ixz="${2.4529790e+03*mm2Tom2}" iyy="${4.4349153e+04*mm2Tom2}" iyz="${4.1006942e+03*mm2Tom2}" izz="${2.3374453e+04*mm2Tom2}" />
    </inertial>
    <visual>
      <origin xyz="0 0 0" rpy="0 0 0"/>
      <geometry name="LThighLowLeg_visual">
        <mesh filename="meshes/HipPitch.STL" scale="0.001 -0.001 0.001" />
      </geometry>
      <material name="grey"/>
    </visual>
    <collision>
      <origin xyz="0 0 0" rpy="0 0 0"/>
      <geometry name="LThighLowLeg_collision">
        <mesh filename="meshes/simple/HipPitch.STL" scale="0.001 -0.001 0.001" />
      </geometry>             
    </collision>
  </link>

  <link name ="LLowLeg">
    <inertial>
      <origin xyz="${-5.0828668*mmTom} ${-3.7732093*mmTom} ${-7.2605017e+01*mmTom}" rpy="0 0 0"/>
      <mass value="5.6495309"/>
      <inertia ixx="${1.0535542e+05*mm2Tom2}"  ixy="${5.8199221e+02*mm2Tom2}"  ixz="${1.6743598e+03*mm2Tom2}" iyy="${9.7857796e+04*mm2Tom2}" iyz="${3.3770181e+03*mm2Tom2}" izz="${2.0854086e+04*mm2Tom2}" />
    </inertial>
    <visual>
      <origin xyz="0 0 0" rpy="0 0 0"/>
      <geometry name="LLowLeg_visual">
        <mesh filename="meshes/KneePitchCalf.STL" scale="0.001 -0.001 0.001" />
      </geometry>
      <material name="dark_grey"/>
    </visual>
    <collision>
      <origin xyz="0 0 0" rpy="0 0 0"/>
      <geometry name="LLowLeg_collision">
        <mesh filename="meshes/simple/KneePitchCalf.STL" scale="0.001 -0.001 0.001" />
      </geometry>             
    </collision>
  </link>

  <link name ="LFootmot">
    <inertial>
      <origin xyz="${-2.2024173e+01*mmTom} ${-2.5677238*mmTom} ${9.4588455e-01*mmTom}" rpy="0 0 0"/>
      <mass value="3.2844159"/>
      <inertia ixx="${7.5550679e+03*mm2Tom2}"  ixy="${-6.7488292e+02*mm2Tom2}"  ixz="${5.8332889e+01*mm2Tom2}" iyy="${1.1241163e+04*mm2Tom2}" iyz="${1.4552081e+02*mm2Tom2}" izz="${1.3391865e+04*mm2Tom2}" />
    </inertial>
    <visual>
      <origin xyz="0 0 0" rpy="0 0 0"/>
      <geometry name="LFootmot_visual">
        <mesh filename="meshes/AnklePitch.STL" scale="0.001 -0.001 0.001" />
      </geometry>
      <material name="dark_grey"/>
    </visual>
    <collision>
      <origin xyz="0 0 0" rpy="0 0 0"/>
      <geometry name="LFootmot_collision">
        <mesh filename="meshes/simple/AnklePitch.STL" scale="0.001 -0.001 0.001" />
      </geometry>             
    </collision>
  </link>

  <link name ="LFoot">
      <inertial> 
        <xacro:if value="${BIGMAN_NEW_FEET}">
          <origin xyz="-0.00653584 0.00479384 -0.10180375" rpy="0 0 0"/>
          <mass value="3.42638110"/>
          <inertia ixx="0.01032886"  ixy="0.00016407"  ixz="-0.00201294" iyy="0.02854025" iyz="-0.00046315" izz="0.02799499" />
        </xacro:if>
        <xacro:unless value="${BIGMAN_NEW_FEET}">
          <origin xyz="0.01282904 0.00463694 -0.10109499" rpy="0 0 0"/>
          <mass value="3.33109981"/>
          <inertia ixx="0.01006627"  ixy="0.00051955"  ixz="-0.00374069" iyy="0.02882577" iyz="-0.00044505" izz="0.02819025" />
        </xacro:unless>
      </inertial>
      <visual>
      <origin xyz="0 0 0" rpy="0 0 0"/>
      <geometry name="LFoot_visual">
        <xacro:if value="${BIGMAN_NEW_FEET}">
              <mesh filename="meshes/NewFoot.STL" scale="0.001 -0.001 0.001"/>
        </xacro:if>
        <xacro:unless value="${BIGMAN_NEW_FEET}">
              <mesh filename="meshes/Foot.STL" scale="0.001 0.001 0.001"/>
        </xacro:unless>
      </geometry>
      <material name="dark_grey"/>
    </visual> 
    <collision>
      <!--
      <origin xyz="0 0 0" rpy="0 0 0"/>
      <geometry name="LFoot_collision">
        <mesh filename="meshes/simple/Foot.STL" scale="0.001 0.001 0.001"/>
      </geometry>
      -->
     <xacro:if value="${BIGMAN_NEW_FEET}">
       <origin xyz="0.005 0.01 -0.1359" rpy="0 0 0"/>
       <geometry>
        <box size="0.32 0.16 0.015" />
       </geometry>
     </xacro:if>
     <xacro:unless value="${BIGMAN_NEW_FEET}">
       <origin xyz="0.047 0.01 -0.1359" rpy="0 0 0"/>
       <geometry>
        <box size="0.306 0.16 0.015" />
       </geometry>
     </xacro:unless>             
    </collision>
   </link>



<!-- JOINTS -->


<!-- ********************RIGHT LEG******************** -->

  <joint name="RHipLat" type="revolute">
    <parent link="Waist"/>
    <child link="RHipMot"/>
    <origin xyz="0.1059 -0.06 0.0" rpy="0 0 0" />
    <axis xyz="1 0 0" />
    <limit velocity="6.283" effort="400" lower="-0.87222" upper="0.697778" />
    <dynamics friction="0" damping="3.0"/>
  </joint>

  <joint name="RHipYaw" type="revolute">
    <parent link="RHipMot"/>
    <child link="RThighUpLeg"/>
    <origin xyz="-0.0889 -0.121032 -0.217872" rpy="0 0 0" />
    <axis xyz="0 0 1" />
    <limit velocity="6.283" effort="140" lower="-1.57" upper="0.872222" />
    <dynamics friction="0" damping="3.0"/>
  </joint>

  <joint name="RHipSag" type="revolute">
    <parent link="RThighUpLeg"/>
    <child link="RThighLowLeg"/>
    <origin xyz="0.0 0.0 0.0" rpy="0 0 0" />
    <axis xyz="0 1 0" />
    <limit velocity="6.283" effort="400" lower="-2.09333" upper="1.046667" />
    <dynamics friction="0" damping="3.0"/>
  </joint>

  <joint name="RKneeSag" type="revolute">
    <parent link="RThighLowLeg"/>
    <child link="RLowLeg"/>
    <origin xyz="0.0 0.0 -0.356" rpy="0 0 0" />
    <axis xyz="0 1 0" />
    <limit velocity="6.283" effort="400" lower="0.0" upper="2.442222" />
    <dynamics friction="0" damping="3.0"/>
  </joint>

  <joint name="RAnkSag" type="revolute">
    <parent link="RLowLeg"/>
    <child link="RFootmot"/>
    <origin xyz="0.0 0.0 -0.4" rpy="0 0 0" />
    <axis xyz="0 1 0" />
    <limit velocity="6.283" effort="330" lower="-1.39556" upper="0.697778" />
    <dynamics friction="0" damping="3.0"/> 
  </joint>

    <joint name="RAnkLat" type="revolute">
      <parent link="RFootmot"/>
      <child link="RFoot"/>
      <origin xyz="0.0 0.0 0.0" rpy="0 0 0" />
      <axis xyz="1 0 0" />
      <limit velocity="6.283" effort="210" lower="-0.785" upper="0.785" />
      <dynamics friction="0" damping="3.0"/>
    </joint>


<!-- ********************LEFT LEG******************** -->

  <joint name="LHipLat" type="revolute">
    <parent link="Waist"/>
    <child link="LHipMot"/>
    <origin xyz="0.1059 0.06 0.0" rpy="0 0 0" />
    <axis xyz="1 0 0" />
    <limit velocity="6.283" effort="400" lower="-0.697778" upper="0.87222" />
    <dynamics friction="0" damping="3.0"/>
  </joint>

  <joint name="LHipYaw" type="revolute">
    <parent link="LHipMot"/>
    <child link="LThighUpLeg"/>
    <origin xyz="-0.0889 0.121032 -0.217872" rpy="0 0 0" />
    <axis xyz="0 0 1" />
    <limit velocity="6.283" effort="140" lower="-0.872222" upper="1.57" />
    <dynamics friction="0" damping="3.0"/>
  </joint>

  <joint name="LHipSag" type="revolute">
    <parent link="LThighUpLeg"/>
    <child link="LThighLowLeg"/>
    <origin xyz="0.0 0.0 0.0" rpy="0 0 0" />
    <axis xyz="0 1 0" />
    <limit velocity="6.283" effort="400" lower="-2.09333" upper="1.046667" />
    <dynamics friction="0" damping="3.0"/>
  </joint>

  <joint name="LKneeSag" type="revolute">
    <parent link="LThighLowLeg"/>
    <child link="LLowLeg"/>
    <origin xyz="0.0 0.0 -0.356" rpy="0 0 0" />
    <axis xyz="0 1 0" />
    <limit velocity="6.283" effort="400" lower="0.0" upper="2.442222" />
    <dynamics friction="0" damping="3.0"/>
  </joint>

  <joint name="LAnkSag" type="revolute">
    <parent link="LLowLeg"/>
    <child link="LFootmot"/>
    <origin xyz="0.0 0.0 -0.4" rpy="0 0 0" />
    <axis xyz="0 1 0" />
    <limit velocity="6.283" effort="330" lower="-1.39556" upper="0.697778" />
    <dynamics friction="0" damping="3.0"/>
  </joint>

  <joint name="LAnkLat" type="revolute">
    <parent link="LFootmot"/>
    <child link="LFoot"/>
    <origin xyz="0.0 0.0 0.0" rpy="0 0 0" />
    <axis xyz="1 0 0" />
    <limit velocity="6.283" effort="210" lower="-0.785" upper="0.785" />
    <dynamics friction="0" damping="3.0"/>
  </joint>


</robot>
