<?xml version="1.0"?>
<robot xmlns:xacro="http://ros.org/wiki/xacro">

<xacro:property name="mmTom" value="0.001" />
<xacro:property name="mm2Tom2" value="${0.001*0.001}" />

<xacro:property name="PI" value="3.14159265359" />
<xacro:property name="PI_2" value="1.57079632679" />

<xacro:property name="cos_26" value="0.89879991307" />
<xacro:property name="sin_26" value="0.43835911792" />

<xacro:property name="toRad" value="${PI/180.0}" />

<!-- LINKS -->
  <link name ="NeckYaw">
    <inertial>
      <origin xyz="0.0 0.0 ${1.1550000e+02*mmTom}" rpy="0 0 0"/>
      <mass value="0.35"/>
      <inertia ixx="${3.2840119e+02*mm2Tom2}"  ixy="0.0"  ixz="0.0" iyy="${7.0371675e+01*mm2Tom2}" iyz="0.0" izz="${3.2840111e+02*mm2Tom2}" />
    </inertial>
    <visual>
      <origin xyz="0.0 0.0 0.0" rpy="0 0 0"/>
      <geometry name="NeckYaw_visual">
        <mesh filename="meshes/NeckYaw.STL" scale="0.001 0.001 0.001" />
      </geometry>
      <material name="grey"/>
    </visual>
    <collision>
      <origin xyz="0.0 0.0 0.0" rpy="0 0 0"/>
      <geometry name="NeckYaw_collision">
        <mesh filename="meshes/simple/NeckYaw.STL" scale="0.001 0.001 0.001" />
      </geometry>             
    </collision>
  </link>

  <link name ="NeckPitch">
    <inertial>
      <origin xyz="${-1.020e+02*mmTom} 0.0 ${2.6575000e+02*mmTom}" rpy="0 0 0"/>
      <mass value="0.623"/>
      <inertia ixx="${1.0388333e+03*mm2Tom2}"  ixy="0.0"  ixz="0.0" iyy="${5.4689381e+02*mm2Tom2}" iyz="0.0" izz="${5.4689381e+02*mm2Tom2}" />
    </inertial>
    <visual>
      <origin xyz="0.0 0.0 0.0" rpy="0 0 0"/>
      <geometry name="NeckPitch_visual">
        <mesh filename="meshes/NeckPitch.STL" scale="0.001 0.001 0.001" />
      </geometry>
      <material name="grey"/>
    </visual>
    <collision>
      <origin xyz="0.0 0.0 0.0" rpy="0 0 0"/>
      <geometry name="NeckPitch_collision">
        <mesh filename="meshes/simple/NeckPitch.STL" scale="0.001 0.001 0.001" />
      </geometry>             
    </collision>
  </link>

<!-- JOINTS -->
<joint name="NeckYawj" type="revolute"> 
    <parent link="DWYTorso"/>
    <child link="NeckYaw"/>
    <origin xyz="0 0 0" rpy="0 0 0" />
    <axis xyz="0 0 1" />
<!--     <limit velocity="6.283" effort="120" lower="${(-175.0)*toRad}" upper="${(175.0)*toRad}" /> -->
    <limit velocity="6.283" effort="120" lower="${(-35.0)*toRad}" upper="${(35.0)*toRad}" />
    <dynamics friction="0" damping="3.0"/> 
</joint>

<joint name="NeckPitchj" type="revolute"> 
    <parent link="NeckYaw"/>
    <child link="NeckPitch"/>
    <origin xyz="0 0 0.117" rpy="0 0 0" />
    <axis xyz="0 1 0" />
    <!--limit velocity="6.283" effort="120" lower="${(-30.0)*toRad}" upper="${(70.0)*toRad}" /-->
    <limit velocity="6.283" effort="120" lower="${(-15.0)*toRad}" upper="${(60.0)*toRad}" />
    <dynamics friction="0" damping="3.0"/> 
</joint>

</robot>
