<mujoco model="target_model">
  <worldbody>
    <!--<body name="target" pos="0 0 .01">-->
    <body name="target" pos="0 0 .01">
      <joint armature="0" axis="1 0 0" damping="0" limited="true" name="target_x" pos="0 0 0" range="-.27 .27" stiffness="0" type="slide"/>
      <joint armature="0" axis="0 1 0" damping="0" limited="true" name="target_y" pos="0 0 0" range="-.27 .27" stiffness="0" type="slide"/>
      <geom conaffinity="0" contype="0" name="target_geo" pos="0 0 0.0" rgba="0.9 0.2 0.2 1" size=".009" type="sphere"/>
    </body>
  </worldbody>
</mujoco>
