<?xml version="1.0" ?>
<!-- =================================================================================== -->
<!-- |    This document was autogenerated by xacro from bigman_robot.urdf.xacro        | -->
<!-- |    EDITING THIS FILE BY HAND IS NOT RECOMMENDED                                 | -->
<!-- =================================================================================== -->
<!--robot xmlns:xacro="http://ros.org/wiki/xacro" name="bigman"-->
<robot name="bigman" xmlns:xacro="http://ros.org/wiki/xacro">
  <!--
  ROS urdf definition of the BIGMAN humanoid robot by Istituto Italiano di Tecnologia
  
  Author: Enrico Mingo
  
  This file groups files to use BIGMAN in GAZEBO
  
  -->
  <!-- Uncomment this to have the robot rigidly connected to the world -->
  <!--  <link name="world"/>
  
   <joint name="fixed" type="fixed">
    <parent link="world"/>
    <child link="base_link"/>
  </joint>
  
  <origin xyz="0.0 0.0 1.5" rpy="0 0 0" /> -->
  <!-- ROBOT -->
  <!-- 
  ROS urdf definition of the BIGMAN humanoid robot by Istituto Italiano di Tecnologia
  
  DO NOT INCLUDE THIS FILE DIRECTLY! USE bigman_robot.urdf.xacro INSTEAD!

  Author: Enrico Mingo & Alessio Rocchi

  Inertial matrix has to be in CoM frame (URDF specs)

  Velocity and effort limits are fake!
-->
  <material name="grey">
    <color rgba="0.5 0.5 0.5 1"/>
  </material>
  <material name="dark_grey">
    <color rgba="0.3 0.3 0.3 1"/>
  </material>
  <material name="blue">
    <color rgba="0.0 0.2 0.3 1"/>
  </material>
  <!-- 
  ROS urdf definition of the BIGMAN humanoid robot by Istituto Italiano di Tecnologia
  
  DO NOT INCLUDE THIS FILE DIRECTLY! USE bigman_robot.urdf.xacro INSTEAD!

  Author: Enrico Mingo & Alessio Rocchi

  Inertial matrix has to be in CoM frame (URDF specs)

  Velocity and effort limits are fake!
-->
  <!--
The coordinate frame called base_link is rigidly attached to the robot root body. It is recommended to choose the robot waist as its root body. The base_link can be attached to the root in any arbitrary position or orientation; for every hardware platform there will be a different place on the base that provides an obvious point of reference. Note that REP 103 [1] specifies a preferred orientation for frames. -->
  <link name="base_link"/>
  <link name="Waist">
    <inertial>
      <origin rpy="0.0 0.0 0.0" xyz="-0.022813402 -0.00073935443 0.030422909"/>
      <mass value="1.1046081e+01"/>
      <inertia ixx="0.096207978" ixy="0.00014081043" ixz="0.0031258127" iyy="0.098511158" iyz="0.00013938149" izz="0.086541531"/>
    </inertial>
    <visual>
      <origin rpy="0 0 0" xyz="0 0 0"/>
      <geometry name="Waist_visual">
        <mesh filename="package://bigman_urdf/meshes/Waist.STL" scale="0.001 0.001 0.001"/>
      </geometry>
      <material name="grey"/>
    </visual>
    <collision>
      <origin rpy="0 0 0" xyz="0 0 0"/>
      <geometry name="Waist_collision">
        <mesh filename="package://bigman_urdf/meshes/simple/Waist.STL" scale="0.001 0.001 0.001"/>
      </geometry>
    </collision>
  </link>
  <joint name="base_joint" type="fixed">
    <parent link="base_link"/>
    <child link="Waist"/>
    <origin rpy="0 0 0" xyz="0 0 0"/>
  </joint>
  <!-- Scale factor for meshes -->
  <!-- LINKS -->
  <!-- This links are defined in order to be compliant with http://www.ros.org/reps/rep-0120.html#coordinate-frames
and to define the end effectors of the robot-->
  <!-- The coordinate frame called torso is attached to the lowest body of the model which is a parent of l_gripper, r_gripper and gaze. -->
  <link name="torso"/>
  <link name="DWL">
    <inertial>
      <origin rpy="0 0 0" xyz="-0.04610869 0.02232230 -0.02249514"/>
      <mass value="1.44965471"/>
      <inertia ixx="0.01096760" ixy="0.00111556" ixz="0.00030030" iyy="0.00409572" iyz="0.00054456" izz="0.01143795"/>
    </inertial>
    <visual>
      <origin rpy="0 0 0" xyz="0.0 0.0 0.0"/>
      <geometry name="DWL_visual">
        <mesh filename="package://bigman_urdf/meshes/TorsoRoll.STL" scale="0.001 0.001 0.001"/>
      </geometry>
      <material name="dark_grey"/>
    </visual>
    <collision>
      <origin rpy="0 0 0" xyz="0.0 0.0 0.0"/>
      <geometry name="DWL_collision">
        <mesh filename="package://bigman_urdf/meshes/simple/TorsoRoll.STL" scale="0.001 0.001 0.001"/>
      </geometry>
    </collision>
  </link>
  <link name="DWS">
    <inertial>
      <origin rpy="0 0 0" xyz="0.00010203 0.00928164 0.08113610"/>
      <mass value="5.28825567"/>
      <inertia ixx="0.01628069" ixy="-0.00000323" ixz="0.00001424" iyy="0.01424286" iyz="0.00075458" izz="0.00994169"/>
    </inertial>
    <visual>
      <origin rpy="0 0 0" xyz="0.0 0.0 0.0"/>
      <geometry name="DWS_visual">
        <mesh filename="package://bigman_urdf/meshes/TorsoYawPitch.STL" scale="0.001 0.001 0.001"/>
      </geometry>
      <material name="dark_grey"/>
    </visual>
    <collision>
      <origin rpy="0 0 0" xyz="0.0 0.0 0.0"/>
      <geometry name="DWS_collision">
        <mesh filename="package://bigman_urdf/meshes/simple/TorsoYawPitch.STL" scale="0.001 0.001 0.001"/>
      </geometry>
    </collision>
  </link>
  <link name="DWYTorso">
    <inertial>
      <origin rpy="0 0 0" xyz="0.0 0.00 0.3"/>
      <mass value="26"/>
      <inertia ixx="0.18629757" ixy="0.00008160" ixz="0.00030250" iyy="0.02013829" iyz="-0.00001790" izz="0.18850541"/>
    </inertial>
    <visual>
      <origin rpy="0 0 0" xyz="0.0 0.0 0.0"/>
      <geometry name="DWYTorso_visual">
        <mesh filename="package://bigman_urdf/meshes/NewChest.STL" scale="0.001 0.001 0.001"/>
      </geometry>
      <material name="blue"/>
    </visual>
    <collision>
      <origin rpy="0 0 0" xyz="0.0 0.0 0.0"/>
      <geometry name="DWYTorso_collision">
        <mesh filename="package://bigman_urdf/meshes/simple/NewChest.STL" scale="0.001 0.001 0.001"/>
      </geometry>
    </collision>
  </link>
  <link name="TorsoProtections">
    <inertial>
      <origin rpy="0 0 0" xyz="-0.082963193 7.0747291e-07 0.075409106"/>
      <mass value="4.7"/>
      <inertia ixx="0.14773769" ixy="0.0" ixz="-0.029780072" iyy="0.16085511" iyz="0.0" izz="0.15409381"/>
    </inertial>
    <visual>
      <origin rpy="0 0 0" xyz="0.0 0.0 0.0"/>
      <geometry name="TorsoProtections_visual">
        <mesh filename="package://bigman_urdf/meshes/ProtectionSystem.STL" scale="0.001 0.001 0.001"/>
      </geometry>
      <material name="dark_grey"/>
    </visual>
    <collision>
      <origin rpy="0 0 0" xyz="0.0 0.0 0.0"/>
      <geometry name="TorsoProtections_collision">
        <mesh filename="package://bigman_urdf/meshes/simple/ProtectionSystem.STL" scale="0.001 0.001 0.001"/>
      </geometry>
    </collision>
  </link>
  <link name="backpack">
    <inertial>
      <origin rpy="0 0 0" xyz="0 0 -0.065"/>
      <mass value="10.0"/>
      <inertia ixx="0.0890833333333" ixy="0.0" ixz="0.0" iyy="0.0354166666667" iyz="0.0" izz="0.0963333333333"/>
    </inertial>
    <visual>
      <origin rpy="0 0 0" xyz="0.0 0.0 0.0"/>
      <geometry name="backpack_visual">
        <box size="0.16 0.3 0.22"/>
      </geometry>
      <material name="dark_grey"/>
    </visual>
    <collision>
      <origin rpy="0 0 0" xyz="0.0 0.0 0.0"/>
      <geometry name="backpack_collision">
        <box size="0.16 0.3 0.22"/>
      </geometry>
    </collision>
  </link>
  <joint name="backpack_joint" type="fixed">
    <parent link="DWYTorso"/>
    <child link="backpack"/>
    <origin rpy="0 0 0" xyz="-0.185 0 -0.025"/>
  </joint>
  <joint name="torso_protection_joint" type="fixed">
    <parent link="DWYTorso"/>
    <child link="TorsoProtections"/>
    <origin rpy="0 0 0" xyz="0.0 0 0.0"/>
  </joint>
  <joint name="torso_joint" type="fixed">
    <parent link="DWYTorso"/>
    <child link="torso"/>
    <origin rpy="0 0 0" xyz="0.0 0 0.0"/>
  </joint>
  <joint name="WaistLat" type="revolute">
    <parent link="Waist"/>
    <child link="DWL"/>
    <origin rpy="0 0 0" xyz="0.1115 0 0.195982"/>
    <axis xyz="0.89879991307 0 0.43835911792"/>
    <limit effort="120" lower="-0.610865238198" upper="0.610865238198" velocity="6.283"/>
    <dynamics damping="3.0" friction="0"/>
  </joint>
  <joint name="WaistSag" type="revolute">
    <parent link="DWL"/>
    <child link="DWS"/>
    <origin rpy="0 0 0" xyz="0 0 0"/>
    <axis xyz="0 1 0"/>
    <limit effort="220" lower="-0.349065850399" upper="1.3962634016" velocity="6.283"/>
    <dynamics damping="3.0" friction="0"/>
  </joint>
  <joint name="WaistYaw" type="revolute">
    <parent link="DWS"/>
    <child link="DWYTorso"/>
    <origin rpy="0 0 0" xyz="0 0 0.22275"/>
    <axis xyz="0 0 1"/>
    <limit effort="120" lower="-2.84488668075" upper="2.84488668075" velocity="6.283"/>
    <dynamics damping="3.0" friction="0"/>
  </joint>
  <!-- LINKS -->
  <link name="NeckYaw">
    <inertial>
      <origin rpy="0 0 0" xyz="0.0 0.0 0.1155"/>
      <mass value="0.35"/>
      <inertia ixx="0.00032840119" ixy="0.0" ixz="0.0" iyy="7.0371675e-05" iyz="0.0" izz="0.00032840111"/>
    </inertial>
    <visual>
      <origin rpy="0 0 0" xyz="0.0 0.0 0.0"/>
      <geometry name="NeckYaw_visual">
        <mesh filename="package://bigman_urdf/meshes/NeckYaw.STL" scale="0.001 0.001 0.001"/>
      </geometry>
      <material name="grey"/>
    </visual>
    <collision>
      <origin rpy="0 0 0" xyz="0.0 0.0 0.0"/>
      <geometry name="NeckYaw_collision">
        <mesh filename="package://bigman_urdf/meshes/simple/NeckYaw.STL" scale="0.001 0.001 0.001"/>
      </geometry>
    </collision>
  </link>
  <link name="NeckPitch">
    <inertial>
      <origin rpy="0 0 0" xyz="-0.102 0.0 0.26575"/>
      <mass value="0.623"/>
      <inertia ixx="0.0010388333" ixy="0.0" ixz="0.0" iyy="0.00054689381" iyz="0.0" izz="0.00054689381"/>
    </inertial>
    <visual>
      <origin rpy="0 0 0" xyz="0.0 0.0 0.0"/>
      <geometry name="NeckPitch_visual">
        <mesh filename="package://bigman_urdf/meshes/NeckPitch.STL" scale="0.001 0.001 0.001"/>
      </geometry>
      <material name="grey"/>
    </visual>
    <collision>
      <origin rpy="0 0 0" xyz="0.0 0.0 0.0"/>
      <geometry name="NeckPitch_collision">
        <mesh filename="package://bigman_urdf/meshes/simple/NeckPitch.STL" scale="0.001 0.001 0.001"/>
      </geometry>
    </collision>
  </link>
  <!-- JOINTS -->
  <joint name="NeckYawj" type="revolute">
    <parent link="DWYTorso"/>
    <child link="NeckYaw"/>
    <origin rpy="0 0 0" xyz="0 0 0"/>
    <axis xyz="0 0 1"/>
    <!--     <limit velocity="6.283" effort="120" lower="${(-175.0)*toRad}" upper="${(175.0)*toRad}" /> -->
    <limit effort="120" lower="-0.610865238198" upper="0.610865238198" velocity="6.283"/>
    <dynamics damping="3.0" friction="0"/>
  </joint>
  <joint name="NeckPitchj" type="revolute">
    <parent link="NeckYaw"/>
    <child link="NeckPitch"/>
    <origin rpy="0 0 0" xyz="0 0 0.117"/>
    <axis xyz="0 1 0"/>
    <!--limit velocity="6.283" effort="120" lower="${(-30.0)*toRad}" upper="${(70.0)*toRad}" /-->
    <limit effort="120" lower="-0.261799387799" upper="1.0471975512" velocity="6.283"/>
    <dynamics damping="3.0" friction="0"/>
  </joint>
  <!-- LINKS -->
  <!-- RIGHT ARM -->
  <link name="RShp">
    <inertial>
      <origin rpy="0 0 0" xyz="-0.00543349 -0.04480023 0.01581062"/>
      <mass value="1.81745527"/>
      <inertia ixx="0.00571053" ixy="0.00041083" ixz="-0.00005130" iyy="0.01126908" iyz="-0.00003461" izz="0.01371197"/>
    </inertial>
    <visual>
      <origin rpy="0 0 0" xyz="0 0 0"/>
      <geometry name="RShp_visual">
        <mesh filename="package://bigman_urdf/meshes/ShoulderPitch.STL" scale="0.001 0.001 0.001"/>
      </geometry>
      <material name="dark_grey"/>
    </visual>
    <collision>
      <origin rpy="0 0 0" xyz="0 0 0"/>
      <geometry name="RShp_collision">
        <mesh filename="package://bigman_urdf/meshes/simple/ShoulderPitch.STL" scale="0.001 0.001 0.001"/>
      </geometry>
    </collision>
  </link>
  <link name="RShr">
    <inertial>
      <origin rpy="0 0 0" xyz="0.00729315 0.00002698 -0.07529696"/>
      <mass value="5.00486460"/>
      <inertia ixx="0.01644345" ixy="-0.00001187" ixz="-0.00010546" iyy="0.01804804" iyz="-0.00000565" izz="0.00802420"/>
    </inertial>
    <visual>
      <origin rpy="0 0 0" xyz="0 0 0"/>
      <geometry name="RShr_visual">
        <mesh filename="package://bigman_urdf/meshes/TopUpperArm.STL" scale="0.001 0.001 0.001"/>
      </geometry>
      <material name="dark_grey"/>
    </visual>
    <collision>
      <origin rpy="0 0 0" xyz="0 0 0"/>
      <geometry name="RShr_collision">
        <mesh filename="package://bigman_urdf/meshes/simple/TopUpperArm.STL" scale="0.001 0.001 0.001"/>
      </geometry>
    </collision>
  </link>
  <link name="RShy">
    <inertial>
      <origin rpy="0 0 0" xyz="0.02765373 -0.03258647 -0.12698781"/>
      <mass value="3.20289133"/>
      <inertia ixx="0.01129046" ixy="0.00013518" ixz="-0.00134760" iyy="0.00984951" iyz="-0.00026836" izz="0.00728549"/>
    </inertial>
    <visual>
      <origin rpy="0 0 0" xyz="0 0 0"/>
      <geometry name="RShy_visual">
        <mesh filename="package://bigman_urdf/meshes/BottomUpperArm.STL" scale="0.001 0.001 0.001"/>
      </geometry>
      <material name="dark_grey"/>
    </visual>
    <collision>
      <origin rpy="0 0 0" xyz="0 0 0"/>
      <geometry name="RShy_collision">
        <mesh filename="package://bigman_urdf/meshes/simple/BottomUpperArm.STL" scale="0.001 0.001 0.001"/>
      </geometry>
    </collision>
  </link>
  <link name="RElb">
    <inertial>
      <origin rpy="0 0 0" xyz="-0.055754915 -0.007582604 -0.043820396"/>
      <mass value="8.6765385e-01"/>
      <inertia ixx="0.0040395238" ixy="0.00034973136" ixz="-0.00068400465" iyy="0.0022460561" iyz="0.00028844444" izz="0.0044895027"/>
    </inertial>
    <visual>
      <origin rpy="0 0 0" xyz="0 0 0"/>
      <geometry name="RElb_visual">
        <mesh filename="package://bigman_urdf/meshes/Elbow.STL" scale="0.001 0.001 0.001"/>
      </geometry>
      <material name="dark_grey"/>
    </visual>
    <collision>
      <origin rpy="0 0 0" xyz="0 0 0"/>
      <geometry name="RElb_collision">
        <mesh filename="package://bigman_urdf/meshes/simple/Elbow.STL" scale="0.001 0.001 0.001"/>
      </geometry>
    </collision>
  </link>
  <!-- LEFT ARM -->
  <link name="LShp">
    <inertial>
      <origin rpy="0 0 0" xyz="-0.00543349 0.04480023 0.01581062"/>
      <mass value="1.81745527"/>
      <inertia ixx="0.00571053" ixy="-0.00041083" ixz="-0.00005130" iyy="0.01126908" iyz="0.00003461" izz="0.01371197"/>
    </inertial>
    <visual>
      <origin rpy="0 0 0" xyz="0 0 0"/>
      <geometry name="LShp_visual">
        <mesh filename="package://bigman_urdf/meshes/ShoulderPitch.STL" scale="0.001 -0.001 0.001"/>
      </geometry>
      <material name="dark_grey"/>
    </visual>
    <collision>
      <origin rpy="0 0 0" xyz="0 0 0"/>
      <geometry name="LShp_collision">
        <mesh filename="package://bigman_urdf/meshes/simple/ShoulderPitch.STL" scale="0.001 -0.001 0.001"/>
      </geometry>
    </collision>
  </link>
  <link name="LShr">
    <inertial>
      <origin rpy="0 0 0" xyz="0.00729315 -0.00002698 -0.07529696"/>
      <mass value="5.00486460"/>
      <inertia ixx="0.01644345" ixy="0.00001187" ixz="-0.00010546" iyy="0.01804804" iyz="0.00000565" izz="0.00802420"/>
    </inertial>
    <visual>
      <origin rpy="0 0 0" xyz="0 0 0"/>
      <geometry name="LShr_visual">
        <mesh filename="package://bigman_urdf/meshes/TopUpperArm.STL" scale="0.001 -0.001 0.001"/>
      </geometry>
      <material name="dark_grey"/>
    </visual>
    <collision>
      <origin rpy="0 0 0" xyz="0 0 0"/>
      <geometry name="LShr_collision">
        <mesh filename="package://bigman_urdf/meshes/simple/TopUpperArm.STL" scale="0.001 -0.001 0.001"/>
      </geometry>
    </collision>
  </link>
  <link name="LShy">
    <inertial>
      <origin rpy="0 0 0" xyz="0.02765373 0.03258647 -0.12698781"/>
      <mass value="3.20289133"/>
      <inertia ixx="0.01129046" ixy="-0.00013518" ixz="-0.00134760" iyy="0.00984951" iyz="0.00026836" izz="0.00728549"/>
    </inertial>
    <visual>
      <origin rpy="0 0 0" xyz="0 0 0"/>
      <geometry name="LShy_visual">
        <mesh filename="package://bigman_urdf/meshes/BottomUpperArm.STL" scale="0.001 -0.001 0.001"/>
      </geometry>
      <material name="dark_grey"/>
    </visual>
    <collision>
      <origin rpy="0 0 0" xyz="0 0 0"/>
      <geometry name="LShy_collision">
        <mesh filename="package://bigman_urdf/meshes/simple/BottomUpperArm.STL" scale="0.001 -0.001 0.001"/>
      </geometry>
    </collision>
  </link>
  <link name="LElb">
    <inertial>
      <origin rpy="0 0 0" xyz="-0.055754915 0.007582604 -0.043820396"/>
      <mass value="8.6765385e-01"/>
      <inertia ixx="0.0040395238" ixy="-0.00034973136" ixz="-0.00068400465" iyy="0.0022460561" iyz="-0.00028844444" izz="0.0044895027"/>
    </inertial>
    <visual>
      <origin rpy="0 0 0" xyz="0 0 0"/>
      <geometry name="LElb_visual">
        <mesh filename="package://bigman_urdf/meshes/Elbow.STL" scale="0.001 -0.001 0.001"/>
      </geometry>
      <material name="dark_grey"/>
    </visual>
    <collision>
      <origin rpy="0 0 0" xyz="0 0 0"/>
      <geometry name="LElb_collision">
        <mesh filename="package://bigman_urdf/meshes/simple/Elbow.STL" scale="0.001 -0.001 0.001"/>
      </geometry>
    </collision>
  </link>
  <!-- JOINTS -->
  <!-- RIGHT ARM -->
  <joint name="RShSag" type="revolute">
    <parent link="DWYTorso"/>
    <child link="RShp"/>
    <origin rpy="0 0 0.3491" xyz="0.045646 -0.219164 0.001531"/>
    <axis xyz="0 0.743144825 -0.669130606"/>
    <limit effort="120" lower="-2.84488668075" upper="2.80998009571" velocity="6.283"/>
    <dynamics damping="3.0" friction="0"/>
  </joint>
  <joint name="RShLat" type="revolute">
    <parent link="RShp"/>
    <child link="RShr"/>
    <origin rpy="0 0 0" xyz="0.0 -0.116568264 0.03364"/>
    <axis xyz="1 0 0"/>
    <limit effort="120" lower="-3.85717764691" upper="-0.12217304764" velocity="6.283"/>
    <dynamics damping="3.0" friction="0"/>
  </joint>
  <joint name="RShYaw" type="revolute">
    <parent link="RShr"/>
    <child link="RShy"/>
    <origin rpy="0 0 0" xyz="0.0 0.0 -0.222"/>
    <axis xyz="0 0 1"/>
    <limit effort="120" lower="-2.86233997327" upper="2.82743338823" velocity="6.283"/>
    <dynamics damping="3.0" friction="0"/>
  </joint>
  <joint name="RElbj" type="revolute">
    <parent link="RShy"/>
    <child link="RElb"/>
    <origin rpy="0 0 0" xyz="0.036 0.0 -0.15"/>
    <axis xyz="0 1 0"/>
    <limit effort="120" lower="-2.96705972839" upper="0.593411945678" velocity="6.283"/>
    <dynamics damping="3.0" friction="0"/>
  </joint>
  <!-- LEFT ARM -->
  <joint name="LShSag" type="revolute">
    <parent link="DWYTorso"/>
    <child link="LShp"/>
    <origin rpy="0 0 -0.3491" xyz="0.045646 0.219164 0.001531"/>
    <axis xyz="0.0 0.743144825 0.669130606"/>
    <limit effort="120" lower="-2.87979326579" upper="2.79252680319" velocity="6.283"/>
    <dynamics damping="3.0" friction="0"/>
  </joint>
  <joint name="LShLat" type="revolute">
    <parent link="LShp"/>
    <child link="LShr"/>
    <origin rpy="0 0 0" xyz="0.0 0.116568264 0.03364"/>
    <axis xyz="1 0 0"/>
    <limit effort="120" lower="0.0872664625997" upper="3.85717764691" velocity="6.283"/>
    <dynamics damping="3.0" friction="0"/>
  </joint>
  <joint name="LShYaw" type="revolute">
    <parent link="LShr"/>
    <child link="LShy"/>
    <origin rpy="0 0 0" xyz="0.0 0.0 -0.222"/>
    <axis xyz="0 0 1"/>
    <limit effort="120" lower="-2.84488668075" upper="2.84488668075" velocity="6.283"/>
    <dynamics damping="3.0" friction="0"/>
  </joint>
  <joint name="LElbj" type="revolute">
    <parent link="LShy"/>
    <child link="LElb"/>
    <origin rpy="0 0 0" xyz="0.036 0.0 -0.15"/>
    <axis xyz="0 1 0"/>
    <limit effort="120" lower="-2.96705972839" upper="0.593411945678" velocity="6.283"/>
    <dynamics damping="3.0" friction="0"/>
  </joint>
  <link name="l_arm_ft"/>
  <link name="r_arm_ft"/>
  <joint name="l_arm_ft_joint" type="fixed">
    <parent link="LWrMot3"/>
    <child link="l_arm_ft"/>
    <origin rpy="0 0 0" xyz="0 0 -0.0565"/>
  </joint>
  <joint name="r_arm_ft_joint" type="fixed">
    <parent link="RWrMot3"/>
    <child link="r_arm_ft"/>
    <origin rpy="0 0 0" xyz="0 0 -0.0565"/>
  </joint>
  <!-- ************ FOREARMS ************ -->
  <!-- This links are defined in order to be compliant with http://www.ros.org/reps/rep-0120.html#coordinate-frames
	and to define the end effectors of the robot -->
  <!-- position and orientation of the arm regardless of the tool (grasping device for instance) attached to it -->
  <link name="l_wrist"/>
  <link name="r_wrist"/>
  <!-- ****************LINKS**************** -->
  <!-- ****************LEFT FOREARM**************** -->
  <link name="LForearm">
    <inertial>
      <origin rpy="0 0 0" xyz="1.2625599e-05 0.0042975381 0.044717986"/>
      <mass value="2.2127686"/>
      <inertia ixx="0.0065428368" ixy="-4.1196967e-05" ixz="3.272727e-06" iyy="0.005587829" iyz="0.00042088668" izz="0.0024783023"/>
    </inertial>
    <visual>
      <origin rpy="0 0 0" xyz="0 0 0"/>
      <geometry name="LForearm_visual">
        <mesh filename="package://bigman_urdf/meshes/Forearm.STL" scale="0.001 -0.001 0.001"/>
      </geometry>
      <material name="dark_grey"/>
    </visual>
    <collision>
      <origin rpy="0 0 0" xyz="0 0 0"/>
      <geometry name="LForearm_collision">
        <mesh filename="package://bigman_urdf/meshes/simple/Forearm.STL" scale="0.001 -0.001 0.001"/>
      </geometry>
    </collision>
  </link>
  <link name="LWrMot2">
    <inertial>
      <origin rpy="0 0 0" xyz="0.009819377 0.0013797184 -0.080380065"/>
      <mass value="1.2838072"/>
      <inertia ixx="0.001994124" ixy="2.569706e-05" ixz="0.00017443538" iyy="0.0021755329" iyz="-0.00012100987" izz="0.001830376"/>
    </inertial>
    <visual>
      <origin rpy="0 0 0" xyz="0 0 0"/>
      <geometry name="LWrMot2_visual">
        <mesh filename="package://bigman_urdf/meshes/ForearmPitch.STL" scale="0.001 -0.001 0.001"/>
      </geometry>
      <material name="dark_grey"/>
    </visual>
    <collision>
      <origin rpy="0 0 0" xyz="0 0 0"/>
      <geometry name="LWrMot2_collision">
        <mesh filename="package://bigman_urdf/meshes/simple/ForearmPitch.STL" scale="0.001 -0.001 0.001"/>
      </geometry>
    </collision>
  </link>
  <link name="LWrMot3">
    <inertial>
      <origin rpy="0 0 0" xyz="0.0070380706 -1.0811188e-05 -0.039669274"/>
      <mass value="4.2801447e-01"/>
      <inertia ixx="0.00028620156" ixy="5.2570457e-08" ixz="-3.9174213e-05" iyy="0.00071261855" iyz="-9.5020266e-08" izz="0.00061444258"/>
    </inertial>
    <visual>
      <origin rpy="0 0 0" xyz="0 0 0"/>
      <geometry name="LWrMot3_visual">
        <mesh filename="package://bigman_urdf/meshes/ForearmRoll.STL" scale="0.001 -0.001 0.001"/>
      </geometry>
      <material name="blue"/>
    </visual>
    <collision>
      <origin rpy="0 0 0" xyz="0 0 0"/>
      <geometry name="LWrMot3_collision">
        <mesh filename="package://bigman_urdf/meshes/simple/ForearmRoll.STL" scale="0.001 -0.001 0.001"/>
      </geometry>
    </collision>
  </link>
  <!-- ****************RIGHT FOREARM**************** -->
  <link name="RForearm">
    <inertial>
      <origin rpy="0 0 0" xyz="1.2625599e-05 -0.0042975381 0.044717986"/>
      <mass value="2.2127686"/>
      <inertia ixx="0.0065428368" ixy="4.1196967e-05" ixz="3.272727e-06" iyy="0.005587829" iyz="-0.00042088668" izz="0.0024783023"/>
    </inertial>
    <visual>
      <origin rpy="0 0 0" xyz="0 0 0"/>
      <geometry name="RForearm_visual">
        <mesh filename="package://bigman_urdf/meshes/Forearm.STL" scale="0.001 0.001 0.001"/>
      </geometry>
      <material name="dark_grey"/>
    </visual>
    <collision>
      <origin rpy="0 0 0" xyz="0 0 0"/>
      <geometry name="RForearm_collision">
        <mesh filename="package://bigman_urdf/meshes/simple/Forearm.STL" scale="0.001 0.001 0.001"/>
      </geometry>
    </collision>
  </link>
  <link name="RWrMot2">
    <inertial>
      <origin rpy="0 0 0" xyz="0.009819377 -0.0013797184 -0.080380065"/>
      <mass value="1.2838072"/>
      <inertia ixx="0.001994124" ixy="-2.569706e-05" ixz="0.00017443538" iyy="0.0021755329" iyz="0.00012100987" izz="0.001830376"/>
    </inertial>
    <visual>
      <origin rpy="0 0 0" xyz="0 0 0"/>
      <geometry name="RWrMot2_visual">
        <mesh filename="package://bigman_urdf/meshes/ForearmPitch.STL" scale="0.001 0.001 0.001"/>
      </geometry>
      <material name="dark_grey"/>
    </visual>
    <collision>
      <origin rpy="0 0 0" xyz="0 0 0"/>
      <geometry name="RWrMot2_collision">
        <mesh filename="package://bigman_urdf/meshes/simple/ForearmPitch.STL" scale="0.001 0.001 0.001"/>
      </geometry>
    </collision>
  </link>
  <link name="RWrMot3">
    <inertial>
      <origin rpy="0 0 0" xyz="0.0070380706 1.0811188e-05 -0.039669274"/>
      <mass value="4.2801447e-01"/>
      <inertia ixx="0.00028620156" ixy="-5.2570457e-08" ixz="-3.9174213e-05" iyy="0.00071261855" iyz="9.5020266e-08" izz="0.00061444258"/>
    </inertial>
    <visual>
      <origin rpy="0 0 0" xyz="0 0 0"/>
      <geometry name="RWrMot3_visual">
        <mesh filename="package://bigman_urdf/meshes/ForearmRoll.STL" scale="0.001 0.001 0.001"/>
      </geometry>
      <material name="blue"/>
    </visual>
    <collision>
      <origin rpy="0 0 0" xyz="0 0 0"/>
      <geometry name="RWrMot3_collision">
        <mesh filename="package://bigman_urdf/meshes/simple/ForearmRoll.STL" scale="0.001 0.001 0.001"/>
      </geometry>
    </collision>
  </link>
  <!-- ****************JOINTS**************** -->
  <!-- ****************LEFT FOREARM**************** -->
  <joint name="LForearmPlate" type="revolute">
    <parent link="LElb"/>
    <child link="LForearm"/>
    <origin rpy="0 0 0" xyz="-0.075 0.0 -0.1955"/>
    <axis xyz="0 0 1"/>
    <limit effort="60" lower="-2.529" upper="2.529" velocity="6.283"/>
    <dynamics damping="0.03" friction="0"/>
  </joint>
  <joint name="LWrj1" type="revolute">
    <parent link="LForearm"/>
    <child link="LWrMot2"/>
    <origin rpy="0 0 0" xyz="0 0 0"/>
    <axis xyz="0 1 0"/>
    <limit effort="60" lower="-1.48" upper="1.48" velocity="6.283"/>
    <dynamics damping="0.03" friction="0"/>
  </joint>
  <joint name="LWrj2" type="revolute">
    <parent link="LWrMot2"/>
    <child link="LWrMot3"/>
    <origin rpy="0 0 0" xyz="0 0 -0.092"/>
    <axis xyz="1 0 0"/>
    <limit effort="60" lower="-1.48" upper="1.48" velocity="6.283"/>
    <dynamics damping="0.03" friction="0"/>
  </joint>
  <joint name="l_wrist_joint" type="fixed">
    <parent link="LWrMot3"/>
    <child link="l_wrist"/>
    <origin rpy="0 0 0" xyz="0 0 0"/>
  </joint>
  <!-- ****************RIGHT FOREARM**************** -->
  <joint name="RForearmPlate" type="revolute">
    <parent link="RElb"/>
    <child link="RForearm"/>
    <origin rpy="0 0 0" xyz="-0.075 0.0 -0.1955"/>
    <axis xyz="0 0 1"/>
    <limit effort="60" lower="-2.529" upper="2.529" velocity="6.283"/>
    <dynamics damping="0.03" friction="0"/>
  </joint>
  <joint name="RWrj1" type="revolute">
    <parent link="RForearm"/>
    <child link="RWrMot2"/>
    <origin rpy="0 0 0" xyz="0 0 0"/>
    <axis xyz="0 1 0"/>
    <limit effort="60" lower="-1.48" upper="1.48" velocity="6.283"/>
    <dynamics damping="0.03" friction="0"/>
  </joint>
  <joint name="RWrj2" type="revolute">
    <parent link="RWrMot2"/>
    <child link="RWrMot3"/>
    <origin rpy="0 0 0" xyz="0 0 -0.092"/>
    <axis xyz="1 0 0"/>
    <limit effort="60" lower="-1.48" upper="1.48" velocity="6.283"/>
    <dynamics damping="0.03" friction="0"/>
  </joint>
  <joint name="r_wrist_joint" type="fixed">
    <parent link="RWrMot3"/>
    <child link="r_wrist"/>
    <origin rpy="0 0 0" xyz="0 0 0"/>
  </joint>
  <!-- LINKS -->
  <!-- ## WRONG NUMBERS FOR... ok lasciamo perde... FIX THEM!! ## -->
  <link name="RSoftHand">
    <inertial>
      <origin rpy="0 0 0" xyz="0 0 -0.17"/>
      <mass value="1.2"/>
      <inertia ixx="0.00232" ixy="0" ixz="0" iyy="0.00296" iyz="0" izz="0.00136"/>
    </inertial>
    <visual>
      <origin rpy="0 0 0" xyz="0 0 0"/>
      <geometry>
        <box size="0.07 0.07 0.07"/>
      </geometry>
      <material name="Cyan">
        <color rgba="0 1.0 1.0 1.0"/>
      </material>
    </visual>
    <collision>
      <origin rpy="0 0 0" xyz="0 0 0"/>
      <geometry>
        <box size="0.07 0.07 0.07"/>
      </geometry>
    </collision>
  </link>
  <link name="LSoftHand">
    <inertial>
      <origin rpy="0 0 0" xyz="0 0 -0.17"/>
      <mass value="1.2"/>
      <inertia ixx="0.00232" ixy="0" ixz="0" iyy="0.00296" iyz="0" izz="0.00136"/>
    </inertial>
    <visual>
      <origin rpy="0 0 0" xyz="0 0 0"/>
      <geometry>
        <box size="0.07 0.07 0.07"/>
      </geometry>
      <material name="Cyan">
        <color rgba="0 1.0 1.0 1.0"/>
      </material>
    </visual>
    <collision>
      <origin rpy="0 0 0" xyz="0 0 0"/>
      <geometry>
        <box size="0.07 0.07 0.07"/>
      </geometry>
    </collision>
  </link>
  <!-- JOINTS -->
  <joint name="r_handj" type="revolute">
    <parent link="RWrMot3"/>
    <child link="RSoftHand"/>
    <origin rpy="0 0 0" xyz="0 0 -0.04"/>
    <axis xyz="1 0 0"/>
    <limit effort="5" lower="0.0" upper="5.0" velocity="4.0"/>
    <dynamics damping="3.0" friction="0"/>
  </joint>
  <joint name="l_handj" type="revolute">
    <parent link="LWrMot3"/>
    <child link="LSoftHand"/>
    <origin rpy="0 0 0" xyz="0 0 -0.04"/>
    <axis xyz="-1 0 0"/>
    <limit effort="5" lower="0" upper="5.0" velocity="4.0"/>
    <dynamics damping="3.0" friction="0"/>
  </joint>
  <joint name="neck_joint" type="fixed">
    <parent link="NeckPitch"/>
    <child link="multisense/head"/>
    <origin rpy="0 0 0" xyz="0.08765 0 0.06475"/>
  </joint>
  <!-- 
       Based on multisense_sl_v4.urdf in multisense_sl_description (DRCSIM) 
-->
  <!-- Head Link Simple Collision Meshes -->
  <link name="multisense/head">
    <inertial>
      <origin rpy="0 0 0" xyz="-0.075493 3.3383E-05 0.02774"/>
      <mass value="1.41984"/>
      <inertia ixx="0.0039688" ixy="-1.5797E-06" ixz="-0.00089293" iyy="0.0041178" iyz="-6.8415E-07" izz="0.0035243"/>
    </inertial>
    <visual>
      <origin rpy="0 0 0" xyz="0 0 0"/>
      <geometry>
        <mesh filename="package://bigman_urdf/meshes/Head.STL" scale="0.001 0.001 0.001"/>
      </geometry>
      <material name="dark_grey"/>
    </visual>
    <collision>
      <origin rpy="0 0 0" xyz="0 0 0"/>
      <geometry>
        <mesh filename="package://bigman_urdf/meshes/simple/Head.STL" scale="0.001 0.001 0.001"/>
      </geometry>
    </collision>
  </link>
  <link name="multisense/hokuyo_link">
    <inertial>
      <origin rpy="0 0 0" xyz="0.032428 0.0004084 -0.0041835"/>
      <mass value="0.057654"/>
      <inertia ixx="3.7174E-05" ixy="4.9927E-08" ixz="1.1015E-05" iyy="4.2412E-05" iyz="-9.8165E-09" izz="4.167E-05"/>
    </inertial>
    <visual>
      <origin rpy="1.5707963267949 0 1.5707963267949" xyz="0 0 0"/>
      <geometry>
        <mesh filename="package://bigman_urdf/meshes/hokuyo_link.STL"/>
      </geometry>
      <material name="black"/>
    </visual>
    <collision>
      <origin rpy="0 0 0" xyz="0.01885 0 -0.02119"/>
      <geometry>
        <box size="0.08 0.06 0.04238"/>
      </geometry>
    </collision>
    <collision>
      <origin rpy="0 0 0" xyz="0.03 0 0.0235"/>
      <geometry>
        <cylinder length="0.047" radius="0.024425"/>
      </geometry>
    </collision>
  </link>
  <joint name="hokuyo_joint" type="fixed">
    <origin rpy="0 0 0" xyz="-0.0446 0 0.0880"/>
    <parent link="multisense/head"/>
    <child link="multisense/hokuyo_link"/>
  </joint>
  <!-- Hokuyo Laser -->
  <joint name="head_hokuyo_joint" type="fixed">
    <axis xyz="0 1 0"/>
    <origin rpy="0 0 0" xyz="0.03 0 0.015"/>
    <parent link="multisense/hokuyo_link"/>
    <child link="multisense/head_hokuyo_frame"/>
  </joint>
  <link name="multisense/head_hokuyo_frame"/>
  <!-- Stereo Camera -->
  <joint name="left_camera_frame_joint" type="fixed">
    <!-- optical frame collocated with tilting DOF -->
    <origin xyz="0.0 0.035 -0.002"/>
    <parent link="multisense/head"/>
    <child link="multisense/left_camera_frame"/>
  </joint>
  <link name="multisense/left_camera_frame"/>
  <joint name="left_camera_optical_frame_joint" type="fixed">
    <origin rpy="-1.5708 0.0 -1.5708" xyz="0 0 0"/>
    <parent link="multisense/left_camera_frame"/>
    <child link="multisense/left_camera_optical_frame"/>
  </joint>
  <link name="multisense/left_camera_optical_frame"/>
  <joint name="right_camera_frame_joint" type="fixed">
    <origin xyz="0.0 -0.035 -0.002"/>
    <parent link="multisense/head"/>
    <child link="multisense/right_camera_frame"/>
  </joint>
  <link name="multisense/right_camera_frame"/>
  <joint name="right_camera_optical_frame_joint" type="fixed">
    <origin rpy="-1.5708 0.0 -1.5708" xyz="0 0 0"/>
    <parent link="multisense/right_camera_frame"/>
    <child link="multisense/right_camera_optical_frame"/>
  </joint>
  <link name="multisense/right_camera_optical_frame"/>
  <joint name="center_top_led_frame_joint" type="fixed">
    <origin xyz="0.01125 0.0 0.0105"/>
    <parent link="multisense/head"/>
    <child link="multisense/center_top_led_frame"/>
  </joint>
  <link name="multisense/center_top_led_frame"/>
  <joint name="center_bottom_led_frame_joint" type="fixed">
    <origin xyz="0.01125 0.0 -0.0155"/>
    <parent link="multisense/head"/>
    <child link="multisense/center_bottom_led_frame"/>
  </joint>
  <link name="multisense/center_bottom_led_frame"/>
  <joint name="left_led_frame_joint" type="fixed">
    <origin rpy="0 0 0.6" xyz="-0.01443 0.07452 0.050346"/>
    <parent link="multisense/head"/>
    <child link="multisense/left_led_frame"/>
  </joint>
  <link name="multisense/left_led_frame"/>
  <joint name="right_led_frame_joint" type="fixed">
    <origin rpy="0 0 -0.6" xyz="-0.01443 -0.07452 0.050346"/>
    <parent link="multisense/head"/>
    <child link="multisense/right_led_frame"/>
  </joint>
  <link name="multisense/right_led_frame"/>
  <!-- imu link -->
  <link name="multisense/head_imu_link">
    <inertial>
      <mass value="1e-5"/>
      <!-- collocate with parent link and remove mass from it -->
      <origin rpy="0 0 0" xyz="-0.122993 0.035033383 0.02774"/>
      <inertia ixx="1e-6" ixy="0" ixz="0" iyy="1e-6" iyz="0" izz="1e-6"/>
    </inertial>
    <visual>
      <origin rpy="0 0 0" xyz="0 0 0"/>
      <geometry>
        <box size="0.01 0.01 0.01"/>
      </geometry>
    </visual>
    <collision>
      <origin rpy="0 0 0" xyz="0 0 0"/>
      <geometry>
        <box size="0.01 0.01 0.01"/>
      </geometry>
    </collision>
  </link>
  <joint name="head_imu_joint" type="fixed">
    <parent link="multisense/head"/>
    <child link="multisense/head_imu_link"/>
    <!-- putting it at the same z-level as the stereo -->
    <origin rpy="0 0 0" xyz="-0.0475 0.035 0.0"/>
  </joint>
  <link name="gaze"/>
  <joint name="gaze_joint" type="fixed">
    <parent link="multisense/head"/>
    <child link="gaze"/>
    <origin rpy="0 0 0" xyz="0 0 0"/>
  </joint>
  <link name="world"/>
  <joint name="fixed" type="fixed">
    <parent link="world"/>
    <child link="base_link"/>
  </joint>
  <origin rpy="0 0 0" xyz="0.0 0.0 1.5"/>
  <gazebo reference="RWrj2">
    <sensor name="r_arm_ft" type="force_torque">
      <force_torque>
        <frame>sensor</frame>
        <measure_direction>child_to_parent</measure_direction>
      </force_torque>
      <always_on>true</always_on>
      <visualize>true</visualize>
      <update_rate>1000</update_rate>
      <pose>0 0 -0.0565 0 0 0</pose>
    </sensor>
  </gazebo>
  <gazebo reference="LWrj2">
    <sensor name="l_arm_ft" type="force_torque">
      <force_torque>
        <frame>sensor</frame>
        <measure_direction>child_to_parent</measure_direction>
      </force_torque>
      <always_on>true</always_on>
      <visualize>true</visualize>
      <update_rate>1000</update_rate>
      <pose>0 0 -0.0565 0 0 0</pose>
    </sensor>
  </gazebo>
  <!-- contact model for hand surface -->
  <gazebo reference="LSoftHand">
    <kp>1000000.0</kp>
    <kd>100.0</kd>
    <mu1>1.0</mu1>
    <mu2>1.0</mu2>
    <fdir1>1 0 0</fdir1>
    <maxVel>1.0</maxVel>
    <minDepth>0.0</minDepth>
  </gazebo>
  <gazebo reference="RSoftHand">
    <kp>1000000.0</kp>
    <kd>100.0</kd>
    <mu1>1.0</mu1>
    <mu2>1.0</mu2>
    <fdir1>1 0 0</fdir1>
    <maxVel>1.0</maxVel>
    <minDepth>0.0</minDepth>
  </gazebo>
  <gazebo reference="LRaisingSupport">
    <kp>1000000.0</kp>
    <kd>100.0</kd>
    <mu1>0.5</mu1>
    <mu2>0.5</mu2>
    <fdir1>1 0 0</fdir1>
    <maxVel>1.0</maxVel>
    <minDepth>0.0</minDepth>
  </gazebo>
  <gazebo reference="RRaisingSupport">
    <kp>1000000.0</kp>
    <kd>100.0</kd>
    <mu1>0.5</mu1>
    <mu2>0.5</mu2>
    <fdir1>1 0 0</fdir1>
    <maxVel>1.0</maxVel>
    <minDepth>0.0</minDepth>
  </gazebo>
  <gazebo reference="WaistSag">
    <implicitSpringDamper>1</implicitSpringDamper>
    <provideFeedback>true</provideFeedback>
  </gazebo>
  <gazebo reference="WaistLat">
    <implicitSpringDamper>1</implicitSpringDamper>
    <provideFeedback>true</provideFeedback>
  </gazebo>
  <gazebo reference="WaistYaw">
    <implicitSpringDamper>1</implicitSpringDamper>
    <provideFeedback>true</provideFeedback>
  </gazebo>
  <gazebo reference="RShSag">
    <implicitSpringDamper>1</implicitSpringDamper>
    <provideFeedback>true</provideFeedback>
  </gazebo>
  <gazebo reference="RShLat">
    <implicitSpringDamper>1</implicitSpringDamper>
    <provideFeedback>true</provideFeedback>
  </gazebo>
  <gazebo reference="RShYaw">
    <implicitSpringDamper>1</implicitSpringDamper>
    <provideFeedback>true</provideFeedback>
  </gazebo>
  <gazebo reference="RElbj">
    <implicitSpringDamper>1</implicitSpringDamper>
    <provideFeedback>true</provideFeedback>
  </gazebo>
  <gazebo reference="RForearmPlate">
    <implicitSpringDamper>1</implicitSpringDamper>
    <provideFeedback>true</provideFeedback>
  </gazebo>
  <gazebo reference="RWrj1">
    <implicitSpringDamper>1</implicitSpringDamper>
    <provideFeedback>true</provideFeedback>
  </gazebo>
  <gazebo reference="RWrj2">
    <implicitSpringDamper>1</implicitSpringDamper>
    <provideFeedback>true</provideFeedback>
  </gazebo>
  <gazebo reference="r_handj">
    <implicitSpringDamper>1</implicitSpringDamper>
    <provideFeedback>true</provideFeedback>
  </gazebo>
  <gazebo reference="LShSag">
    <implicitSpringDamper>1</implicitSpringDamper>
    <provideFeedback>true</provideFeedback>
  </gazebo>
  <gazebo reference="LShLat">
    <implicitSpringDamper>1</implicitSpringDamper>
    <provideFeedback>true</provideFeedback>
  </gazebo>
  <gazebo reference="LShYaw">
    <implicitSpringDamper>1</implicitSpringDamper>
    <provideFeedback>true</provideFeedback>
  </gazebo>
  <gazebo reference="LElbj">
    <implicitSpringDamper>1</implicitSpringDamper>
    <provideFeedback>true</provideFeedback>
  </gazebo>
  <gazebo reference="LForearmPlate">
    <implicitSpringDamper>1</implicitSpringDamper>
    <provideFeedback>true</provideFeedback>
  </gazebo>
  <gazebo reference="LWrj1">
    <implicitSpringDamper>1</implicitSpringDamper>
    <provideFeedback>true</provideFeedback>
  </gazebo>
  <gazebo reference="LWrj2">
    <implicitSpringDamper>1</implicitSpringDamper>
    <provideFeedback>true</provideFeedback>
  </gazebo>
  <gazebo reference="l_handj">
    <implicitSpringDamper>1</implicitSpringDamper>
    <provideFeedback>true</provideFeedback>
  </gazebo>
  <gazebo>
    <plugin filename="libGazeboXBotPlugin.so" name="xbot_plugin_handler">
      <path_to_config_file>configs/ADVR_shared/bigman/configs/config_walkman.yaml</path_to_config_file>
    </plugin>
  </gazebo>
  <gazebo reference="base_link">
    <material>Gazebo/Grey</material>
  </gazebo>
  <gazebo reference="DWL">
    <material>Gazebo/DarkGrey</material>
  </gazebo>
  <gazebo reference="DWS">
    <material>Gazebo/DarkGrey</material>
  </gazebo>
  <gazebo reference="DWYTorso">
    <material>Gazebo/Blue</material>
  </gazebo>
  <gazebo reference="RShp">
    <material>Gazebo/DarkGrey</material>
  </gazebo>
  <gazebo reference="RShr">
    <material>Gazebo/DarkGrey</material>
  </gazebo>
  <gazebo reference="RShy">
    <material>Gazebo/DarkGrey</material>
  </gazebo>
  <gazebo reference="RElb">
    <material>Gazebo/DarkGrey</material>
  </gazebo>
  <gazebo reference="RForearm">
    <material>Gazebo/DarkGrey</material>
  </gazebo>
  <gazebo reference="RWrMot2">
    <material>Gazebo/DarkGrey</material>
  </gazebo>
  <gazebo reference="RWrMot3">
    <material>Gazebo/Blue</material>
  </gazebo>
  <gazebo reference="RRaisingSupport">
    <material>Gazebo/DarkGrey</material>
  </gazebo>
  <gazebo reference="RSoftHand">
    <material>Gazebo/Black</material>
  </gazebo>
  <gazebo reference="LShp">
    <material>Gazebo/DarkGrey</material>
  </gazebo>
  <gazebo reference="LShr">
    <material>Gazebo/DarkGrey</material>
  </gazebo>
  <gazebo reference="LShy">
    <material>Gazebo/DarkGrey</material>
  </gazebo>
  <gazebo reference="LElb">
    <material>Gazebo/DarkGrey</material>
  </gazebo>
  <gazebo reference="LForearm">
    <material>Gazebo/DarkGrey</material>
  </gazebo>
  <gazebo reference="LWrMot2">
    <material>Gazebo/DarkGrey</material>
  </gazebo>
  <gazebo reference="LWrMot3">
    <material>Gazebo/Blue</material>
  </gazebo>
  <gazebo reference="LRaisingSupport">
    <material>Gazebo/DarkGrey</material>
  </gazebo>
  <gazebo reference="LSoftHand">
    <material>Gazebo/Black</material>
  </gazebo>
  <gazebo reference="RHipMot">
    <material>Gazebo/DarkGrey</material>
  </gazebo>
  <gazebo reference="RThighUpLeg">
    <material>Gazebo/DarkGrey</material>
  </gazebo>
  <gazebo reference="RThighLowLeg">
    <material>Gazebo/Grey</material>
  </gazebo>
  <gazebo reference="RLowLeg">
    <material>Gazebo/DarkGrey</material>
  </gazebo>
  <gazebo reference="RFootmot">
    <material>Gazebo/DarkGrey</material>
  </gazebo>
  <gazebo reference="RFoot">
    <material>Gazebo/DarkGrey</material>
  </gazebo>
  <gazebo reference="LHipMot">
    <material>Gazebo/DarkGrey</material>
  </gazebo>
  <gazebo reference="LThighUpLeg">
    <material>Gazebo/DarkGrey</material>
  </gazebo>
  <gazebo reference="LThighLowLeg">
    <material>Gazebo/Grey</material>
  </gazebo>
  <gazebo reference="LLowLeg">
    <material>Gazebo/DarkGrey</material>
  </gazebo>
  <gazebo reference="LFootmot">
    <material>Gazebo/DarkGrey</material>
  </gazebo>
  <gazebo reference="LFoot">
    <material>Gazebo/DarkGrey</material>
  </gazebo>
  <gazebo reference="head">
    <material>Gazebo/DarkGrey</material>
  </gazebo>
  <gazebo reference="hokuyo_link">
    <material>Gazebo/Black</material>
  </gazebo>
  <gazebo reference="NeckYaw">
    <material>Gazebo/Grey</material>
  </gazebo>
  <gazebo reference="NeckPitch">
    <material>Gazebo/Grey</material>
  </gazebo>
</robot>

